Workbook
Name Slicer_Year: #N/A

Sheet 01_Executive_Overview
B2: Trade Structure and Balance Overview
B3: Source: UN COMTRADE | Values in USD
B5: Exports | C5: Imports | D5: Trade Balance | E5: =Pivot_Backend!B12 -> Export-to-Import Ratio %
B6: =GETPIVOTDATA("[Measures].[TotalTradeValueUSD_Export]",Pivot_Backend!$B$2) -> 435596355042 | C6: =GETPIVOTDATA("[Measures].[TotalTradeValueUSD_Import]",Pivot_Backend!$E$2) -> 751217254065 | D6: =GETPIVOTDATA("[Measures].[TradeBalance]",Pivot_Backend!$H$2) -> -315620899023 | E6: =GETPIVOTDATA("[Measures].[Export-to-Import Ratio %]",Pivot_Backend!$B$12) -> 0.57985403
B8: =Pivot_Backend!C5 -> Export YoY %
B9: =Pivot_Backend!B6 -> 2020 | C9: =Pivot_Backend!B7 -> 2021 | D9: =Pivot_Backend!B8 -> 2022 | E9: =Pivot_Backend!B9 -> 2023 | F9: =Pivot_Backend!B10 -> 2024
B10: =GETPIVOTDATA("[Measures].[Export YoY %]",Pivot_Backend!$B$5,"[Dim_Date].[Year]","[Dim_Date].[Year].&[2020]") -> -0.080537251 | C10: =GETPIVOTDATA("[Measures].[Export YoY %]",Pivot_Backend!$B$5,"[Dim_Date].[Year]","[Dim_Date].[Year].&[2021]") -> 0.14421797 | D10: =GETPIVOTDATA("[Measures].[Export YoY %]",Pivot_Backend!$B$5,"[Dim_Date].[Year]","[Dim_Date].[Year].&[2022]") -> 0.057746134 | E10: =GETPIVOTDATA("[Measures].[Export YoY %]",Pivot_Backend!$B$5,"[Dim_Date].[Year]","[Dim_Date].[Year].&[2023]") -> -0.076084454 | F10: =GETPIVOTDATA("[Measures].[Export YoY %]",Pivot_Backend!$B$5,"[Dim_Date].[Year]","[Dim_Date].[Year].&[2024]") -> 0.00083140687
B12: =Pivot_Backend!F5 -> Import YoY %
B13: =Pivot_Backend!E6 -> 2020 | C13: =Pivot_Backend!E7 -> 2021 | D13: =Pivot_Backend!E8 -> 2022 | E13: =Pivot_Backend!E9 -> 2023 | F13: =Pivot_Backend!E10 -> 2024
B14: =GETPIVOTDATA("[Measures].[Import YoY %]",Pivot_Backend!$E$5,"[Dim_Date].[Year]","[Dim_Date].[Year].&[2020]") -> -0.18917681 | C14: =GETPIVOTDATA("[Measures].[Import YoY %]",Pivot_Backend!$E$5,"[Dim_Date].[Year]","[Dim_Date].[Year].&[2021]") -> 0.30845307 | D14: =GETPIVOTDATA("[Measures].[Import YoY %]",Pivot_Backend!$E$5,"[Dim_Date].[Year]","[Dim_Date].[Year].&[2022]") -> 0.17275901 | E14: =GETPIVOTDATA("[Measures].[Import YoY %]",Pivot_Backend!$E$5,"[Dim_Date].[Year]","[Dim_Date].[Year].&[2023]") -> -0.083139413 | F14: =GETPIVOTDATA("[Measures].[Import YoY %]",Pivot_Backend!$E$5,"[Dim_Date].[Year]","[Dim_Date].[Year].&[2024]") -> 0.00844435
B16: =Pivot_Backend!I5 -> Trade Balance YoY %
B17: =Pivot_Backend!H6 -> 2020 | C17: =Pivot_Backend!H7 -> 2021 | D17: =Pivot_Backend!H8 -> 2022 | E17: =Pivot_Backend!H9 -> 2023 | F17: =Pivot_Backend!H10 -> 2024
B18: =GETPIVOTDATA("[Measures].[Trade Balance YoY %]",Pivot_Backend!$H$5,"[Dim_Date].[Year]","[Dim_Date].[Year].&[2020]") -> -0.35552708 | C18: =GETPIVOTDATA("[Measures].[Trade Balance YoY %]",Pivot_Backend!$H$5,"[Dim_Date].[Year]","[Dim_Date].[Year].&[2021]") -> 0.6672353 | D18: =GETPIVOTDATA("[Measures].[Trade Balance YoY %]",Pivot_Backend!$H$5,"[Dim_Date].[Year]","[Dim_Date].[Year].&[2022]") -> 0.34519317 | E18: =GETPIVOTDATA("[Measures].[Trade Balance YoY %]",Pivot_Backend!$H$5,"[Dim_Date].[Year]","[Dim_Date].[Year].&[2023]") -> -0.09145644 | F18: =GETPIVOTDATA("[Measures].[Trade Balance YoY %]",Pivot_Backend!$H$5,"[Dim_Date].[Year]","[Dim_Date].[Year].&[2024]") -> 0.017571028
B20: Trade Concentration: Top 1 and Top 5 Partner Contributions | I20: Top 1 Export Share %
B21: =Pivot_Backend!B16 -> 2019 | D21: =Pivot_Backend!B17 -> 2020 | F21: =Pivot_Backend!B18 -> 2021 | I21: Top 5 Export Share %
B22: =Pivot_Backend!C15 -> Top 1 Export Share % | C22: =Pivot_Backend!D15 -> Top 5 Export Share % | D22: =Pivot_Backend!C15 -> Top 1 Export Share % | E22: =Pivot_Backend!D15 -> Top 5 Export Share % | F22: =Pivot_Backend!C15 -> Top 1 Export Share % | G22: =Pivot_Backend!D15 -> Top 5 Export Share % | I22: Top 1 Import Share %
B23: =GETPIVOTDATA("[Measures].[Top 1 Export Share %]",Pivot_Backend!$B$15,"[Dim_Date].[Year]","[Dim_Date].[Year].&[2019]") -> 0.16318079 | C23: =GETPIVOTDATA("[Measures].[Top 5 Export Share %]",Pivot_Backend!$B$15,"[Dim_Date].[Year]","[Dim_Date].[Year].&[2019]") -> 0.64178822 | D23: =GETPIVOTDATA("[Measures].[Top 1 Export Share %]",Pivot_Backend!$B$15,"[Dim_Date].[Year]","[Dim_Date].[Year].&[2020]") -> 0.15386699 | E23: =GETPIVOTDATA("[Measures].[Top 5 Export Share %]",Pivot_Backend!$B$15,"[Dim_Date].[Year]","[Dim_Date].[Year].&[2020]") -> 0.65769197 | F23: =GETPIVOTDATA("[Measures].[Top 1 Export Share %]",Pivot_Backend!$B$15,"[Dim_Date].[Year]","[Dim_Date].[Year].&[2021]") -> 0.15892163 | G23: =GETPIVOTDATA("[Measures].[Top 5 Export Share %]",Pivot_Backend!$B$15,"[Dim_Date].[Year]","[Dim_Date].[Year].&[2021]") -> 0.64645452 | I23: Top 5 Import Share %
B24: =Pivot_Backend!E15 -> Top 1 Import Share % | C24: =Pivot_Backend!F15 -> Top 5 Import Share % | D24: =Pivot_Backend!E15 -> Top 1 Import Share % | E24: =Pivot_Backend!F15 -> Top 5 Import Share % | F24: =Pivot_Backend!E15 -> Top 1 Import Share % | G24: =Pivot_Backend!F15 -> Top 5 Import Share %
B25: =GETPIVOTDATA("[Measures].[Top 1 Import Share %]",Pivot_Backend!$B$15,"[Dim_Date].[Year]","[Dim_Date].[Year].&[2019]") -> 0.22820474 | C25: =GETPIVOTDATA("[Measures].[Top 5 Import Share %]",Pivot_Backend!$B$15,"[Dim_Date].[Year]","[Dim_Date].[Year].&[2019]") -> 0.53381854 | D25: =GETPIVOTDATA("[Measures].[Top 1 Import Share %]",Pivot_Backend!$B$15,"[Dim_Date].[Year]","[Dim_Date].[Year].&[2020]") -> 0.23152228 | E25: =GETPIVOTDATA("[Measures].[Top 5 Import Share %]",Pivot_Backend!$B$15,"[Dim_Date].[Year]","[Dim_Date].[Year].&[2020]") -> 0.54693928 | F25: =GETPIVOTDATA("[Measures].[Top 1 Import Share %]",Pivot_Backend!$B$15,"[Dim_Date].[Year]","[Dim_Date].[Year].&[2021]") -> 0.22678864 | G25: =GETPIVOTDATA("[Measures].[Top 5 Import Share %]",Pivot_Backend!$B$15,"[Dim_Date].[Year]","[Dim_Date].[Year].&[2021]") -> 0.53847597
B26: =Pivot_Backend!B19 -> 2022 | D26: =Pivot_Backend!B20 -> 2023 | F26: =Pivot_Backend!B21 -> 2024
B27: =Pivot_Backend!C15 -> Top 1 Export Share % | C27: =Pivot_Backend!D15 -> Top 5 Export Share % | D27: =Pivot_Backend!C15 -> Top 1 Export Share % | E27: =Pivot_Backend!D15 -> Top 5 Export Share % | F27: =Pivot_Backend!C15 -> Top 1 Export Share % | G27: =Pivot_Backend!D15 -> Top 5 Export Share %
B28: =GETPIVOTDATA("[Measures].[Top 1 Export Share %]",Pivot_Backend!$B$15,"[Dim_Date].[Year]","[Dim_Date].[Year].&[2022]") -> 0.15807896 | C28: =GETPIVOTDATA("[Measures].[Top 5 Export Share %]",Pivot_Backend!$B$15,"[Dim_Date].[Year]","[Dim_Date].[Year].&[2022]") -> 0.63253018 | D28: =GETPIVOTDATA("[Measures].[Top 1 Export Share %]",Pivot_Backend!$B$15,"[Dim_Date].[Year]","[Dim_Date].[Year].&[2023]") -> 0.15672625 | E28: =GETPIVOTDATA("[Measures].[Top 5 Export Share %]",Pivot_Backend!$B$15,"[Dim_Date].[Year]","[Dim_Date].[Year].&[2023]") -> 0.61428637 | F28: =GETPIVOTDATA("[Measures].[Top 1 Export Share %]",Pivot_Backend!$B$15,"[Dim_Date].[Year]","[Dim_Date].[Year].&[2024]") -> 0.16609623 | G28: =GETPIVOTDATA("[Measures].[Top 5 Export Share %]",Pivot_Backend!$B$15,"[Dim_Date].[Year]","[Dim_Date].[Year].&[2024]") -> 0.61608018
B29: =Pivot_Backend!E15 -> Top 1 Import Share % | C29: =Pivot_Backend!F15 -> Top 5 Import Share % | D29: =Pivot_Backend!E15 -> Top 1 Import Share % | E29: =Pivot_Backend!F15 -> Top 5 Import Share % | F29: =Pivot_Backend!E15 -> Top 1 Import Share % | G29: =Pivot_Backend!F15 -> Top 5 Import Share %
B30: =GETPIVOTDATA("[Measures].[Top 1 Import Share %]",Pivot_Backend!$B$15,"[Dim_Date].[Year]","[Dim_Date].[Year].&[2022]") -> 0.20425242 | C30: =GETPIVOTDATA("[Measures].[Top 5 Import Share %]",Pivot_Backend!$B$15,"[Dim_Date].[Year]","[Dim_Date].[Year].&[2022]") -> 0.54317857 | D30: =GETPIVOTDATA("[Measures].[Top 1 Import Share %]",Pivot_Backend!$B$15,"[Dim_Date].[Year]","[Dim_Date].[Year].&[2023]") -> 0.23127859 | E30: =GETPIVOTDATA("[Measures].[Top 5 Import Share %]",Pivot_Backend!$B$15,"[Dim_Date].[Year]","[Dim_Date].[Year].&[2023]") -> 0.53929539 | F30: =GETPIVOTDATA("[Measures].[Top 1 Import Share %]",Pivot_Backend!$B$15,"[Dim_Date].[Year]","[Dim_Date].[Year].&[2024]") -> 0.25576473 | G30: =GETPIVOTDATA("[Measures].[Top 5 Import Share %]",Pivot_Backend!$B$15,"[Dim_Date].[Year]","[Dim_Date].[Year].&[2024]") -> 0.55847646

Sheet 02_Partner_Structure
B2: Trade Partner Structure (Top Export and Import Partners)
B3: Source: UN COMTRADE | Values shown as % of Total Trade
C23: Export Concentration | L23: Import Concentration
C24: Largest Partner Share | E24: =Pivot_Backend!$L3 -> 0.15952172 | L24: Largest Partner Share | N24: =Pivot_Backend!$S3 -> 0.22923444
C25: Top 5 Partner Share | E25: =SUM(Pivot_Backend!$L3:$L7) -> 0.63293571 | L25: Top 5 Partner Share | N25: =SUM(Pivot_Backend!$S3:$S7) -> 0.54347028

Sheet 03_Sector_Composition
B2: Trade Sector Composition
B3: Source: UN COMTRADE | Values shown as % of Total Trade
E27: Export Concentration | R27: Import Concentration
E28: Largest Sector Share | H28: =Pivot_Backend!$Z17 -> 0.63654361 | R28: Largest Sector Share | U28: =Pivot_Backend!$Z35 -> 0.32234028
E29: Top 5 Sector Share | H29: =SUM(Pivot_Backend!$Z13:$Z17) -> 0.83175124 | R29: Top 5 Sector Share | U29: =SUM(Pivot_Backend!$Z31:$Z35) -> 0.71954321

Sheet 04_Trade_Balance_Analysis
B2: Trade Balance
B3: Source: UN COMTRADE | Values in USD
G29: Largest Surplus Sector
G30: =Pivot_Backend!$AF17 -> Machinery/Electrical | J30: =Pivot_Backend!$AI17 -> 35128497620
G31: Largest Deficit Sector
G32: =Pivot_Backend!$AF3 -> Mineral Products | J32: =Pivot_Backend!$AI3 -> -103200417946

Sheet Pivot_Backend
B2: Total Export (USD) | E2: Total Import (USD) | H2: Trade Balance (USD) | L2: TotalTradeValueUSD_Export | S2: TotalTradeValueUSD_Import | Z2: By Sector Export Share % | AG2: TradeBalance
B3: 435596355042 | E3: 751217254065 | H3: -315620899023 | K3: USA,PR,USVI | L3: 0.15952172 | M3: =$K12 -> Asia Othr.ns | N3: =$L12 -> 0.034825568 | O3: =IF($N3=MAX($N$3:$N$12), MAX($N$3:$N$12), NA()) -> #N/A | P3: =IF($N3<>MAX($N$3:$N$12), $N3, NA()) -> 0.034825568 | R3: China | S3: 0.22923444 | T3: =$R12 -> Viet Nam | U3: =$S12 -> 0.036127871 | V3: =IF($U3=MAX($U$3:$U$12), MAX($U$3:$U$12), NA()) -> #N/A | W3: =IF($U3<>MAX($U$3:$U$12), $U3, NA()) -> 0.036127871 | Y3: Footwear/Headgear | Z3: 0.002176267 | AA3: =$Y3 -> Footwear/Headgear | AB3: =$Z3 -> 0.002176267 | AC3: =IF($AB3=MAX($AB$3:$AB$17), MAX($AB$3:$AB$17), NA()) -> #N/A | AD3: =IF($AB3<>MAX($AB$3:$AB$17), $AB3, NA()) -> 0.002176267 | AF3: Mineral Products | AG3: -103200417946 | AH3: =$AF3 -> Mineral Products | AI3: =$AG3 -> -103200417946 | AJ3: =IF($AI3>0, $AI3, NA()) -> #N/A | AK3: =IF($AI3<0, $AI3, NA()) -> -103200417946
K4: Japan | L4: 0.14510045 | M4: =$K11 -> Netherlands | N4: =$L11 -> 0.03519894 | O4: =IF($N4=MAX($N$3:$N$12), MAX($N$3:$N$12), NA()) -> #N/A | P4: =IF($N4<>MAX($N$3:$N$12), $N4, NA()) -> 0.03519894 | R4: Japan | S4: 0.089120931 | T4: =$R11 -> Asia Othr.ns | U4: =$S11 -> 0.04274063 | V4: =IF($U4=MAX($U$3:$U$12), MAX($U$3:$U$12), NA()) -> #N/A | W4: =IF($U4<>MAX($U$3:$U$12), $U4, NA()) -> 0.04274063 | Y4: Animal & Animal Products | Z4: 0.0058687739 | AA4: =$Y4 -> Animal & Animal Products | AB4: =$Z4 -> 0.0058687739 | AC4: =IF($AB4=MAX($AB$3:$AB$17), MAX($AB$3:$AB$17), NA()) -> #N/A | AD4: =IF($AB4<>MAX($AB$3:$AB$17), $AB4, NA()) -> 0.0058687739 | AF4: Transportation | AG4: -51693306526 | AH4: =$AF4 -> Transportation | AI4: =$AG4 -> -51693306526 | AJ4: =IF($AI4>0, $AI4, NA()) -> #N/A | AK4: =IF($AI4<0, $AI4, NA()) -> -51693306526
C5: Export YoY % | F5: Import YoY % | I5: Trade Balance YoY % | K5: China | L5: 0.14281988 | M5: =$K10 -> Germany | N5: =$L10 -> 0.036164311 | O5: =IF($N5=MAX($N$3:$N$12), MAX($N$3:$N$12), NA()) -> #N/A | P5: =IF($N5<>MAX($N$3:$N$12), $N5, NA()) -> 0.036164311 | R5: Indonesia | S5: 0.079817356 | T5: =$R10 -> Malaysia | U5: =$S10 -> 0.0451003 | V5: =IF($U5=MAX($U$3:$U$12), MAX($U$3:$U$12), NA()) -> #N/A | W5: =IF($U5<>MAX($U$3:$U$12), $U5, NA()) -> 0.0451003 | Y5: Raw Hides, Skins, Leather, & Furs | Z5: 0.0094478373 | AA5: =$Y5 -> Raw Hides, Skins, Leather, & Furs | AB5: =$Z5 -> 0.0094478373 | AC5: =IF($AB5=MAX($AB$3:$AB$17), MAX($AB$3:$AB$17), NA()) -> #N/A | AD5: =IF($AB5<>MAX($AB$3:$AB$17), $AB5, NA()) -> 0.0094478373 | AF5: Chemicals and Allied Industries | AG5: -51109567241 | AH5: =$AF5 -> Chemicals and Allied Industries | AI5: =$AG5 -> -51109567241 | AJ5: =IF($AI5>0, $AI5, NA()) -> #N/A | AK5: =IF($AI5<0, $AI5, NA()) -> -51109567241
B6: 2020 | C6: -0.080537251 | E6: 2020 | F6: -0.18917681 | H6: 2020 | I6: -0.35552708 | K6: Hong Kong | L6: 0.13231111 | M6: =$K9 -> Thailand | N6: =$L9 -> 0.042606122 | O6: =IF($N6=MAX($N$3:$N$12), MAX($N$3:$N$12), NA()) -> #N/A | P6: =IF($N6<>MAX($N$3:$N$12), $N6, NA()) -> 0.042606122 | R6: Korea Rep. | S6: 0.076226286 | T6: =$R9 -> Singapore | U6: =$S9 -> 0.055789121 | V6: =IF($U6=MAX($U$3:$U$12), MAX($U$3:$U$12), NA()) -> #N/A | W6: =IF($U6<>MAX($U$3:$U$12), $U6, NA()) -> 0.055789121 | Y6: Wood and Wood Products | Z6: 0.011502727 | AA6: =$Y6 -> Wood and Wood Products | AB6: =$Z6 -> 0.011502727 | AC6: =IF($AB6=MAX($AB$3:$AB$17), MAX($AB$3:$AB$17), NA()) -> #N/A | AD6: =IF($AB6<>MAX($AB$3:$AB$17), $AB6, NA()) -> 0.011502727 | AF6: Metals | AG6: -32506634466 | AH6: =$AF6 -> Metals | AI6: =$AG6 -> -32506634466 | AJ6: =IF($AI6>0, $AI6, NA()) -> #N/A | AK6: =IF($AI6<0, $AI6, NA()) -> -32506634466
B7: 2021 | C7: 0.14421797 | E7: 2021 | F7: 0.30845307 | H7: 2021 | I7: 0.6672353 | K7: Singapore | L7: 0.053182538 | M7: =$K8 -> Korea Rep. | N7: =$L8 -> 0.043250087 | O7: =IF($N7=MAX($N$3:$N$12), MAX($N$3:$N$12), NA()) -> #N/A | P7: =IF($N7<>MAX($N$3:$N$12), $N7, NA()) -> 0.043250087 | R7: USA,PR,USVI | S7: 0.06907127 | T7: =$R8 -> Thailand | U7: =$S8 -> 0.057638879 | V7: =IF($U7=MAX($U$3:$U$12), MAX($U$3:$U$12), NA()) -> #N/A | W7: =IF($U7<>MAX($U$3:$U$12), $U7, NA()) -> 0.057638879 | Y7: Textiles | Z7: 0.01407115 | AA7: =$Y7 -> Textiles | AB7: =$Z7 -> 0.01407115 | AC7: =IF($AB7=MAX($AB$3:$AB$17), MAX($AB$3:$AB$17), NA()) -> #N/A | AD7: =IF($AB7<>MAX($AB$3:$AB$17), $AB7, NA()) -> 0.01407115 | AF7: Foodstuffs | AG7: -28440225590 | AH7: =$AF7 -> Foodstuffs | AI7: =$AG7 -> -28440225590 | AJ7: =IF($AI7>0, $AI7, NA()) -> #N/A | AK7: =IF($AI7<0, $AI7, NA()) -> -28440225590
B8: 2022 | C8: 0.057746134 | E8: 2022 | F8: 0.17275901 | H8: 2022 | I8: 0.34519317 | K8: Korea Rep. | L8: 0.043250087 | M8: =$K7 -> Singapore | N8: =$L7 -> 0.053182538 | O8: =IF($N8=MAX($N$3:$N$12), MAX($N$3:$N$12), NA()) -> #N/A | P8: =IF($N8<>MAX($N$3:$N$12), $N8, NA()) -> 0.053182538 | R8: Thailand | S8: 0.057638879 | T8: =$R7 -> USA,PR,USVI | U8: =$S7 -> 0.06907127 | V8: =IF($U8=MAX($U$3:$U$12), MAX($U$3:$U$12), NA()) -> #N/A | W8: =IF($U8<>MAX($U$3:$U$12), $U8, NA()) -> 0.06907127 | Y8: Chemicals and Allied Industries | Z8: 0.017059165 | AA8: =$Y8 -> Chemicals and Allied Industries | AB8: =$Z8 -> 0.017059165 | AC8: =IF($AB8=MAX($AB$3:$AB$17), MAX($AB$3:$AB$17), NA()) -> #N/A | AD8: =IF($AB8<>MAX($AB$3:$AB$17), $AB8, NA()) -> 0.017059165 | AF8: Plastics/Rubbers | AG8: -20181539105 | AH8: =$AF8 -> Plastics/Rubbers | AI8: =$AG8 -> -20181539105 | AJ8: =IF($AI8>0, $AI8, NA()) -> #N/A | AK8: =IF($AI8<0, $AI8, NA()) -> -20181539105
B9: 2023 | C9: -0.076084454 | E9: 2023 | F9: -0.083139413 | H9: 2023 | I9: -0.09145644 | K9: Thailand | L9: 0.042606122 | M9: =$K6 -> Hong Kong | N9: =$L6 -> 0.13231111 | O9: =IF($N9=MAX($N$3:$N$12), MAX($N$3:$N$12), NA()) -> #N/A | P9: =IF($N9<>MAX($N$3:$N$12), $N9, NA()) -> 0.13231111 | R9: Singapore | S9: 0.055789121 | T9: =$R6 -> Korea Rep. | U9: =$S6 -> 0.076226286 | V9: =IF($U9=MAX($U$3:$U$12), MAX($U$3:$U$12), NA()) -> #N/A | W9: =IF($U9<>MAX($U$3:$U$12), $U9, NA()) -> 0.076226286 | Y9: Plastics/Rubbers | Z9: 0.022486611 | AA9: =$Y9 -> Plastics/Rubbers | AB9: =$Z9 -> 0.022486611 | AC9: =IF($AB9=MAX($AB$3:$AB$17), MAX($AB$3:$AB$17), NA()) -> #N/A | AD9: =IF($AB9<>MAX($AB$3:$AB$17), $AB9, NA()) -> 0.022486611 | AF9: Animal & Animal Products | AG9: -19886952477 | AH9: =$AF9 -> Animal & Animal Products | AI9: =$AG9 -> -19886952477 | AJ9: =IF($AI9>0, $AI9, NA()) -> #N/A | AK9: =IF($AI9<0, $AI9, NA()) -> -19886952477
B10: 2024 | C10: 0.00083140687 | E10: 2024 | F10: 0.00844435 | H10: 2024 | I10: 0.017571028 | K10: Germany | L10: 0.036164311 | M10: =$K5 -> China | N10: =$L5 -> 0.14281988 | O10: =IF($N10=MAX($N$3:$N$12), MAX($N$3:$N$12), NA()) -> #N/A | P10: =IF($N10<>MAX($N$3:$N$12), $N10, NA()) -> 0.14281988 | R10: Malaysia | S10: 0.0451003 | T10: =$R5 -> Indonesia | U10: =$S5 -> 0.079817356 | V10: =IF($U10=MAX($U$3:$U$12), MAX($U$3:$U$12), NA()) -> #N/A | W10: =IF($U10<>MAX($U$3:$U$12), $U10, NA()) -> 0.079817356 | Y10: Stone/Glass | Z10: 0.023516646 | AA10: =$Y10 -> Stone/Glass | AB10: =$Z10 -> 0.023516646 | AC10: =IF($AB10=MAX($AB$3:$AB$17), MAX($AB$3:$AB$17), NA()) -> #N/A | AD10: =IF($AB10<>MAX($AB$3:$AB$17), $AB10, NA()) -> 0.023516646 | AF10: Vegetable Products | AG10: -16328422766 | AH10: =$AF10 -> Vegetable Products | AI10: =$AG10 -> -16328422766 | AJ10: =IF($AI10>0, $AI10, NA()) -> #N/A | AK10: =IF($AI10<0, $AI10, NA()) -> -16328422766
K11: Netherlands | L11: 0.03519894 | M11: =$K4 -> Japan | N11: =$L4 -> 0.14510045 | O11: =IF($N11=MAX($N$3:$N$12), MAX($N$3:$N$12), NA()) -> #N/A | P11: =IF($N11<>MAX($N$3:$N$12), $N11, NA()) -> 0.14510045 | R11: Asia Othr.ns | S11: 0.04274063 | T11: =$R4 -> Japan | U11: =$S4 -> 0.089120931 | V11: =IF($U11=MAX($U$3:$U$12), MAX($U$3:$U$12), NA()) -> #N/A | W11: =IF($U11<>MAX($U$3:$U$12), $U11, NA()) -> 0.089120931 | Y11: Transportation | Z11: 0.027998608 | AA11: =$Y11 -> Transportation | AB11: =$Z11 -> 0.027998608 | AC11: =IF($AB11=MAX($AB$3:$AB$17), MAX($AB$3:$AB$17), NA()) -> #N/A | AD11: =IF($AB11<>MAX($AB$3:$AB$17), $AB11, NA()) -> 0.027998608 | AF11: Wood and Wood Products | AG11: -10022505362 | AH11: =$AF11 -> Wood and Wood Products | AI11: =$AG11 -> -10022505362 | AJ11: =IF($AI11>0, $AI11, NA()) -> #N/A | AK11: =IF($AI11<0, $AI11, NA()) -> -10022505362
B12: Export-to-Import Ratio % | K12: Asia Othr.ns | L12: 0.034825568 | M12: =$K3 -> USA,PR,USVI | N12: =$L3 -> 0.15952172 | O12: =IF($N12=MAX($N$3:$N$12), MAX($N$3:$N$12), NA()) -> 0.15952172 | P12: =IF($N12<>MAX($N$3:$N$12), $N12, NA()) -> #N/A | R12: Viet Nam | S12: 0.036127871 | T12: =$R3 -> China | U12: =$S3 -> 0.22923444 | V12: =IF($U12=MAX($U$3:$U$12), MAX($U$3:$U$12), NA()) -> 0.22923444 | W12: =IF($U12<>MAX($U$3:$U$12), $U12, NA()) -> #N/A | Y12: Foodstuffs | Z12: 0.034120974 | AA12: =$Y12 -> Foodstuffs | AB12: =$Z12 -> 0.034120974 | AC12: =IF($AB12=MAX($AB$3:$AB$17), MAX($AB$3:$AB$17), NA()) -> #N/A | AD12: =IF($AB12<>MAX($AB$3:$AB$17), $AB12, NA()) -> 0.034120974 | AF12: Miscellaneous | AG12: -9371603478 | AH12: =$AF12 -> Miscellaneous | AI12: =$AG12 -> -9371603478 | AJ12: =IF($AI12>0, $AI12, NA()) -> #N/A | AK12: =IF($AI12<0, $AI12, NA()) -> -9371603478
B13: 0.57985403 | K13: Malaysia | L13: 0.028284601 | R13: Hong Kong | S13: 0.02340764 | Y13: Mineral Products | Z13: 0.041325937 | AA13: =$Y13 -> Mineral Products | AB13: =$Z13 -> 0.041325937 | AC13: =IF($AB13=MAX($AB$3:$AB$17), MAX($AB$3:$AB$17), NA()) -> #N/A | AD13: =IF($AB13<>MAX($AB$3:$AB$17), $AB13, NA()) -> 0.041325937 | AF13: Textiles | AG13: -6791951556 | AH13: =$AF13 -> Textiles | AI13: =$AG13 -> -6791951556 | AJ13: =IF($AI13>0, $AI13, NA()) -> #N/A | AK13: =IF($AI13<0, $AI13, NA()) -> -6791951556
K14: Viet Nam | L14: 0.021249378 | R14: Australia | S14: 0.019044894 | Y14: Miscellaneous | Z14: 0.047618514 | AA14: =$Y14 -> Miscellaneous | AB14: =$Z14 -> 0.047618514 | AC14: =IF($AB14=MAX($AB$3:$AB$17), MAX($AB$3:$AB$17), NA()) -> #N/A | AD14: =IF($AB14<>MAX($AB$3:$AB$17), $AB14, NA()) -> 0.047618514 | AF14: Footwear/Headgear | AG14: -2293360501 | AH14: =$AF14 -> Footwear/Headgear | AI14: =$AG14 -> -2293360501 | AJ14: =IF($AI14>0, $AI14, NA()) -> #N/A | AK14: =IF($AI14<0, $AI14, NA()) -> -2293360501
C15: Top 1 Export Share % | D15: Top 5 Export Share % | E15: Top 1 Import Share % | F15: Top 5 Import Share % | K15: India | L15: 0.010907248 | R15: Germany | S15: 0.018356301 | Y15: Metals | Z15: 0.051073288 | AA15: =$Y15 -> Metals | AB15: =$Z15 -> 0.051073288 | AC15: =IF($AB15=MAX($AB$3:$AB$17), MAX($AB$3:$AB$17), NA()) -> #N/A | AD15: =IF($AB15<>MAX($AB$3:$AB$17), $AB15, NA()) -> 0.051073288 | AF15: Stone/Glass | AG15: -535060352 | AH15: =$AF15 -> Stone/Glass | AI15: =$AG15 -> -535060352 | AJ15: =IF($AI15>0, $AI15, NA()) -> #N/A | AK15: =IF($AI15<0, $AI15, NA()) -> -535060352
B16: 2019 | C16: 0.16318079 | D16: 0.64178822 | E16: 0.22820474 | F16: 0.53381854 | K16: Indonesia | L16: 0.010735698 | R16: India | S16: 0.016937488 | Y16: Vegetable Products | Z16: 0.055189895 | AA16: =$Y16 -> Vegetable Products | AB16: =$Z16 -> 0.055189895 | AC16: =IF($AB16=MAX($AB$3:$AB$17), MAX($AB$3:$AB$17), NA()) -> #N/A | AD16: =IF($AB16<>MAX($AB$3:$AB$17), $AB16, NA()) -> 0.055189895 | AF16: Raw Hides, Skins, Leather, & Furs | AG16: 1612150723 | AH16: =$AF16 -> Raw Hides, Skins, Leather, & Furs | AI16: =$AG16 -> 1612150723 | AJ16: =IF($AI16>0, $AI16, NA()) -> 1612150723 | AK16: =IF($AI16<0, $AI16, NA()) -> #N/A
B17: 2020 | C17: 0.15386699 | D17: 0.65769197 | E17: 0.23152228 | F17: 0.54693928 | K17: Mexico | L17: 0.010482735 | R17: Saudi Arabia | S17: 0.014783676 | Y17: Machinery/Electrical | Z17: 0.63654361 | AA17: =$Y17 -> Machinery/Electrical | AB17: =$Z17 -> 0.63654361 | AC17: =IF($AB17=MAX($AB$3:$AB$17), MAX($AB$3:$AB$17), NA()) -> 0.63654361 | AD17: =IF($AB17<>MAX($AB$3:$AB$17), $AB17, NA()) -> #N/A | AF17: Machinery/Electrical | AG17: 35128497620 | AH17: =$AF17 -> Machinery/Electrical | AI17: =$AG17 -> 35128497620 | AJ17: =IF($AI17>0, $AI17, NA()) -> 35128497620 | AK17: =IF($AI17<0, $AI17, NA()) -> #N/A
B18: 2021 | C18: 0.15892163 | D18: 0.64645452 | E18: 0.22678864 | F18: 0.53847597 | K18: France+Monac | L18: 0.0082971658 | R18: Brazil | S18: 0.011544866 | Y18: Grand Total | Z18: 1 | AF18: Grand Total | AG18: -315620899023
B19: 2022 | C19: 0.15807896 | D19: 0.63253018 | E19: 0.20425242 | F19: 0.54317857 | K19: Canada | L19: 0.0074328464 | R19: Untd Arab Em | S19: 0.010195628
B20: 2023 | C20: 0.15672625 | D20: 0.61428637 | E20: 0.23127859 | F20: 0.53929539 | K20: Switz.Liecht | L20: 0.0072224038 | R20: France+Monac | S20: 0.0092908012 | Z20: By Sector Import Share %
B21: 2024 | C21: 0.16609623 | D21: 0.61608018 | E21: 0.25576473 | F21: 0.55847646 | K21: Untd.Kingdom | L21: 0.0068695589 | R21: Italy | S21: 0.007428039 | Y21: Raw Hides, Skins, Leather, & Furs | Z21: 0.0033323153 | AA21: =$Y21 -> Raw Hides, Skins, Leather, & Furs | AB21: =$Z21 -> 0.0033323153 | AC21: =IF($AB21=MAX($AB$21:$AB$35), MAX($AB$21:$AB$35), NA()) -> #N/A | AD21: =IF($AB21<>MAX($AB$21:$AB$35), $AB21, NA()) -> 0.0033323153
B22: Grand Total | C22: 0.15952172 | D22: 0.63293571 | E22: 0.22923444 | F22: 0.54347028 | K22: Australia | L22: 0.0067650136 | R22: Canada | S22: 0.0064686834 | Y22: Footwear/Headgear | Z22: 0.0043147764 | AA22: =$Y22 -> Footwear/Headgear | AB22: =$Z22 -> 0.0043147764 | AC22: =IF($AB22=MAX($AB$21:$AB$35), MAX($AB$21:$AB$35), NA()) -> #N/A | AD22: =IF($AB22<>MAX($AB$21:$AB$35), $AB22, NA()) -> 0.0043147764
K23: Untd Arab Em | L23: 0.0045613915 | R23: Untd.Kingdom | S23: 0.0058290028 | Y23: Stone/Glass | Z23: 0.01434848 | AA23: =$Y23 -> Stone/Glass | AB23: =$Z23 -> 0.01434848 | AC23: =IF($AB23=MAX($AB$21:$AB$35), MAX($AB$21:$AB$35), NA()) -> #N/A | AD23: =IF($AB23<>MAX($AB$21:$AB$35), $AB23, NA()) -> 0.01434848
C24: 2019 | D24: 2020 | E24: 2021 | F24: 2022 | G24: 2023 | H24: 2024 | K24: Czech Rep | L24: 0.0038031606 | R24: Spain | S24: 0.0054813015 | Y24: Textiles | Z24: 0.017200474 | AA24: =$Y24 -> Textiles | AB24: =$Z24 -> 0.017200474 | AC24: =IF($AB24=MAX($AB$21:$AB$35), MAX($AB$21:$AB$35), NA()) -> #N/A | AD24: =IF($AB24<>MAX($AB$21:$AB$35), $AB24, NA()) -> 0.017200474
B25: T1E | C25: ='01_Executive_Overview'!B23 -> 0.16318079 | D25: ='01_Executive_Overview'!D23 -> 0.15386699 | E25: ='01_Executive_Overview'!F23 -> 0.15892163 | F25: ='01_Executive_Overview'!B28 -> 0.15807896 | G25: ='01_Executive_Overview'!D28 -> 0.15672625 | H25: ='01_Executive_Overview'!F28 -> 0.16609623 | K25: Italy | L25: 0.0034586547 | R25: Netherlands | S25: 0.0051489681 | Y25: Wood and Wood Products | Z25: 0.020011589 | AA25: =$Y25 -> Wood and Wood Products | AB25: =$Z25 -> 0.020011589 | AC25: =IF($AB25=MAX($AB$21:$AB$35), MAX($AB$21:$AB$35), NA()) -> #N/A | AD25: =IF($AB25<>MAX($AB$21:$AB$35), $AB25, NA()) -> 0.020011589
B26: T5E | C26: ='01_Executive_Overview'!C23 -> 0.64178822 | D26: ='01_Executive_Overview'!E23 -> 0.65769197 | E26: ='01_Executive_Overview'!G23 -> 0.64645452 | F26: ='01_Executive_Overview'!C28 -> 0.63253018 | G26: ='01_Executive_Overview'!E28 -> 0.61428637 | H26: ='01_Executive_Overview'!G28 -> 0.61608018 | K26: Spain | L26: 0.0033309399 | R26: Russian Fed | S26: 0.0046875362 | Y26: Animal & Animal Products | Z26: 0.029876003 | AA26: =$Y26 -> Animal & Animal Products | AB26: =$Z26 -> 0.029876003 | AC26: =IF($AB26=MAX($AB$21:$AB$35), MAX($AB$21:$AB$35), NA()) -> #N/A | AD26: =IF($AB26<>MAX($AB$21:$AB$35), $AB26, NA()) -> 0.029876003
B27: T1I | C27: ='01_Executive_Overview'!B25 -> 0.22820474 | D27: ='01_Executive_Overview'!D25 -> 0.23152228 | E27: ='01_Executive_Overview'!F25 -> 0.22678864 | F27: ='01_Executive_Overview'!B30 -> 0.20425242 | G27: ='01_Executive_Overview'!D30 -> 0.23127859 | H27: ='01_Executive_Overview'!F30 -> 0.25576473 | K27: Belgium | L27: 0.0031801406 | R27: Belgium | S27: 0.0044813818 | Y27: Plastics/Rubbers | Z27: 0.039904068 | AA27: =$Y27 -> Plastics/Rubbers | AB27: =$Z27 -> 0.039904068 | AC27: =IF($AB27=MAX($AB$21:$AB$35), MAX($AB$21:$AB$35), NA()) -> #N/A | AD27: =IF($AB27<>MAX($AB$21:$AB$35), $AB27, NA()) -> 0.039904068
B28: T5I | C28: ='01_Executive_Overview'!C25 -> 0.53381854 | D28: ='01_Executive_Overview'!E25 -> 0.54693928 | E28: ='01_Executive_Overview'!G25 -> 0.53847597 | F28: ='01_Executive_Overview'!C30 -> 0.54317857 | G28: ='01_Executive_Overview'!E30 -> 0.53929539 | H28: ='01_Executive_Overview'!G30 -> 0.55847646 | K28: Poland | L28: 0.003021446 | R28: New Zealand | S28: 0.0041341957 | Y28: Miscellaneous | Z28: 0.040087011 | AA28: =$Y28 -> Miscellaneous | AB28: =$Z28 -> 0.040087011 | AC28: =IF($AB28=MAX($AB$21:$AB$35), MAX($AB$21:$AB$35), NA()) -> #N/A | AD28: =IF($AB28<>MAX($AB$21:$AB$35), $AB28, NA()) -> 0.040087011
K29: Ireland | L29: 0.0027641964 | R29: Argentina | S29: 0.0033731557 | Y29: Vegetable Products | Z29: 0.053738036 | AA29: =$Y29 -> Vegetable Products | AB29: =$Z29 -> 0.053738036 | AC29: =IF($AB29=MAX($AB$21:$AB$35), MAX($AB$21:$AB$35), NA()) -> #N/A | AD29: =IF($AB29<>MAX($AB$21:$AB$35), $AB29, NA()) -> 0.053738036
K30: Brazil | L30: 0.0026878956 | R30: Switz.Liecht | S30: 0.0028410075 | Y30: Foodstuffs | Z30: 0.05764404 | AA30: =$Y30 -> Foodstuffs | AB30: =$Z30 -> 0.05764404 | AC30: =IF($AB30=MAX($AB$21:$AB$35), MAX($AB$21:$AB$35), NA()) -> #N/A | AD30: =IF($AB30<>MAX($AB$21:$AB$35), $AB30, NA()) -> 0.05764404
K31: Hungary | L31: 0.0019390907 | R31: Qatar | S31: 0.002695799 | Y31: Metals | Z31: 0.072887001 | AA31: =$Y31 -> Metals | AB31: =$Z31 -> 0.072887001 | AC31: =IF($AB31=MAX($AB$21:$AB$35), MAX($AB$21:$AB$35), NA()) -> #N/A | AD31: =IF($AB31<>MAX($AB$21:$AB$35), $AB31, NA()) -> 0.072887001
K32: Austria | L32: 0.0018039457 | R32: Kuwait | S32: 0.0026944577 | Y32: Chemicals and Allied Industries | Z32: 0.077927493 | AA32: =$Y32 -> Chemicals and Allied Industries | AB32: =$Z32 -> 0.077927493 | AC32: =IF($AB32=MAX($AB$21:$AB$35), MAX($AB$21:$AB$35), NA()) -> #N/A | AD32: =IF($AB32<>MAX($AB$21:$AB$35), $AB32, NA()) -> 0.077927493
K33: South Africa | L33: 0.0014798232 | R33: Israel | S33: 0.0024686748 | Y33: Transportation | Z33: 0.085047831 | AA33: =$Y33 -> Transportation | AB33: =$Z33 -> 0.085047831 | AC33: =IF($AB33=MAX($AB$21:$AB$35), MAX($AB$21:$AB$35), NA()) -> #N/A | AD33: =IF($AB33<>MAX($AB$21:$AB$35), $AB33, NA()) -> 0.085047831
K34: Israel | L34: 0.0013518727 | R34: Brunei Darsm | S34: 0.002423551 | Y34: Mineral Products | Z34: 0.1613406 | AA34: =$Y34 -> Mineral Products | AB34: =$Z34 -> 0.1613406 | AC34: =IF($AB34=MAX($AB$21:$AB$35), MAX($AB$21:$AB$35), NA()) -> #N/A | AD34: =IF($AB34<>MAX($AB$21:$AB$35), $AB34, NA()) -> 0.1613406
K35: Saudi Arabia | L35: 0.0013321798 | R35: Ireland | S35: 0.002368941 | Y35: Machinery/Electrical | Z35: 0.32234028 | AA35: =$Y35 -> Machinery/Electrical | AB35: =$Z35 -> 0.32234028 | AC35: =IF($AB35=MAX($AB$21:$AB$35), MAX($AB$21:$AB$35), NA()) -> 0.32234028 | AD35: =IF($AB35<>MAX($AB$21:$AB$35), $AB35, NA()) -> #N/A
K36: Denmark | L36: 0.0012157327 | R36: Mexico | S36: 0.0021937974 | Y36: Grand Total | Z36: 1
K37: Argentina | L37: 0.001190904 | R37: Iraq | S37: 0.0019118685
K38: Russian Fed | L38: 0.0010783645 | R38: Denmark | S38: 0.0019082122
K39: Turkey | L39: 0.00096570275 | R39: Papua N.Guin | S39: 0.0016891275
K40: Bulgaria | L40: 0.00092330674 | R40: Myanmar | S40: 0.0016327763
K41: New Zealand | L41: 0.00084858083 | R41: Sweden | S41: 0.0015905567
...
